Workbook

Sheet README
A1: French elections nested logit: estimation data and 2027 manifestos
A3: What this workbook contains
A4: Elections | B4: Seven national first-round elections 2017-2024: registered voters, valid votes, outside option (abstention, blank, null).
A5: Votes | B5: Votes for each scored party or list (official results) and the shares used in the regression, computed by formula.
A6: Positions | B6: Party characteristics 0-10 (Chapel Hill Expert Survey 2019 / 2024 where available, constructed codings otherwise).
A7: Composites | B7: Weights used to build Ensemble, NUPES and NFP from their member parties.
A8: Fiscal | B8: Promised fiscal gain by income group (0 = large loss, 5 = neutral, 10 = large gain), coded from manifestos.
A9: Income survey | B9: Vote by household income (Ipsos post-election surveys) used for the income-group coefficients.
A10: Estimation data | B10: The 60 observations as entered in the regression: characteristics, dependent variable, within-nest share, instruments, election dummies; fitted values and residuals by formula.
A11: Coefficients | B11: Estimated coefficients (2SLS, robust s.e.), election fixed effects, presidential intercept, party factors X_j (by formula from the residuals), income-group coefficients.
A12: Manifestos 2027 | B12: INPUT SHEET: one row per 2027 candidate. Yellow cells are inputs. The sheet predicts the first round with the national nested logit.
A14: Model
A15: Equation | B15: ln s_jt - ln s_0t = sum_k beta_k (x_jk - 5) + sigma ln s_j|g,t + lambda_t + xi_jt ; xi_jt = X_j + eps_jt
A16: Specification | B16: Characteristics: tax cuts, immigration control, spending control, European integration, support for Israel. Nests: Left / Centre / Right. Estimator: 2SLS, within-nest share instrumented by the number of rivals in the nest and the sum of their characteristics.
A17: Source of the estimates | B17: Estimated in logit2027v4.html (default specification). Excel does not run the 2SLS itself: the coefficients are stored as values; everything downstream (fitted values, residuals, party factors, 2027 prediction) is recalculated by formula.
A19: Colour code
A20: Blue text | B20: Hard-coded input data (results, scores, estimates).
A21: Black text | B21: Formulas.
A22: Green text | B22: Links to another sheet.
A23: Yellow fill | B23: Cells you are expected to edit (2027 manifestos, settings).
A25: Manifesto inputs | B25: The 2027 rows are pre-filled with each party's 2024 positions (the "Load a 2027 field" default of the HTML page). Replace them with your own manifesto scores, or copy the values from the HTML page's "Export manifestos (JSON)" file.
A26: Note | B26: The workbook reproduces the national-model prediction of the HTML page with the party factor from presidential elections. The income-group prediction and the simulation ranges are only in the HTML page.

Sheet Manifestos 2027
A1: 2027 presidential first round: manifesto inputs and prediction
A2: Edit the yellow cells. One row per candidate (up to 20); leave the name empty to drop a row. Party factor code: one of the codes in Coefficients!A37:A50, or NEW for a new party (X_j = 0).
A4: Settings
A5: Registered voters | B5: 49332709 | C5: Default: registered at the 2024 legislative election.
A6: Minor unlisted candidates (share of valid votes) | B6: 0.023 | C6: Default: average of 2017 and 2022.
A7: sigma | B7: =MAX(0,MIN(0.95,Coefficients!D16)) -> 0.79179748
A8: lambda_P presidential intercept | B8: =Coefficients!D28 -> -0.48154177
A9: gamma, promised fiscal gain | B9: =Coefficients!D17 -> 0.057890855
D11: beta per point → | E11: =Coefficients!D5 -> -0.035747289 | F11: =Coefficients!D6 -> 0.1054539 | G11: =Coefficients!D7 -> -0.037615351 | H11: =Coefficients!D8 -> 0.043685654 | I11: =Coefficients!D9 -> 0.0051190743 | J11: =Coefficients!D10 -> 0 | K11: =Coefficients!D11 -> 0 | L11: =Coefficients!D12 -> 0 | M11: =Coefficients!D13 -> 0 | N11: =Coefficients!D14 -> 0 | O11: Income weights →
N12: weights → | O12: ='Income survey'!D35 -> 0.12 | P12: ='Income survey'!D36 -> 0.47 | Q12: ='Income survey'!D37 -> 0.41
A13: Candidate | B13: Party factor code | C13: Nest (L/C/R) | D13: Key pledges | E13: Tax cuts | F13: Immigration control | G13: Spending control | H13: European integration | I13: Support for Israel | J13: Redistribution | K13: Law and order | L13: Climate action | M13: Other environment | N13: Defence vs Russia | O13: Fiscal gain: poor | P13: Fiscal gain: middle | Q13: Fiscal gain: rich | R13: Candidate effect (shift) | S13: Coded fiscal: poor | T13: Coded fiscal: middle | U13: Coded fiscal: rich | V13: Positions sum beta(x-5) | W13: Fiscal change gamma*w*(f-coded) | X13: Party factor X_j | Y13: Utility U | Z13: exp(U/(1-sigma)) | AA13: Share of registered | AB13: Predicted % of valid votes | AC13: Predicted votes | AD13: Rank
A14: LO / NPA | B14: LONPA | C14: L | E14: 0 | F14: 0 | G14: 0 | H14: 2 | I14: 0.5 | J14: 10 | K14: 0.5 | L14: 6 | M14: 6 | N14: 3 | O14: 9.5 | P14: 6 | Q14: 0.5 | R14: 0 | S14: =IF($A14="","",IF($B14="NEW",5,INDEX(Fiscal!C:C,MATCH($B14,Fiscal!$A:$A,0)))) -> 9.5 | T14: =IF($A14="","",IF($B14="NEW",5,INDEX(Fiscal!D:D,MATCH($B14,Fiscal!$A:$A,0)))) -> 6 | U14: =IF($A14="","",IF($B14="NEW",5,INDEX(Fiscal!E:E,MATCH($B14,Fiscal!$A:$A,0)))) -> 0.5 | V14: =IF($A14="","",SUMPRODUCT($E$11:$N$11,E14:N14-5)) -> -0.31454911 | W14: =IF($A14="","",$B$9*SUMPRODUCT($O$12:$Q$12,O14:Q14-S14:U14)) -> 0 | X14: =IF($A14="","",IF($B14="NEW",0,INDEX(Coefficients!$F$37:$F$50,MATCH($B14,Coefficients!$A$37:$A$50,0)))) -> 0.0080975116 | Y14: =IF($A14="","",$B$8+V14+W14+X14+N(R14)) -> -0.78799337 | Z14: =IF($A14="","",EXP(Y14/(1-$B$7))) -> 0.022714662 | AA14: =IF($A14="","",Z14*INDEX($C$38:$C$40,MATCH($C14,$A$38:$A$40,0))^(-$B$7)/$B$42) -> 0.012003806 | AB14: =IF($A14="","",AA14*(1-$B$6)/$B$43) -> 0.015979244 | AC14: =IF($A14="","",AA14/$B$45*$B$5) -> 582122.42 | AD14: =IF($A14="","",RANK(AB14,$AB$14:$AB$33)) -> 10
A15: La France insoumise | B15: LFI | C15: L | E15: 1 | F15: 1.55 | G15: 1 | H15: 3.33 | I15: 1 | J15: 9 | K15: 2 | L15: 7.75 | M15: 6.67 | N15: 5 | O15: 9 | P15: 6.5 | Q15: 1 | R15: 0 | S15: =IF($A15="","",IF($B15="NEW",5,INDEX(Fiscal!C:C,MATCH($B15,Fiscal!$A:$A,0)))) -> 9 | T15: =IF($A15="","",IF($B15="NEW",5,INDEX(Fiscal!D:D,MATCH($B15,Fiscal!$A:$A,0)))) -> 6.5 | U15: =IF($A15="","",IF($B15="NEW",5,INDEX(Fiscal!E:E,MATCH($B15,Fiscal!$A:$A,0)))) -> 1 | V15: =IF($A15="","",SUMPRODUCT($E$11:$N$11,E15:N15-5)) -> -0.16379674 | W15: =IF($A15="","",$B$9*SUMPRODUCT($O$12:$Q$12,O15:Q15-S15:U15)) -> 0 | X15: =IF($A15="","",IF($B15="NEW",0,INDEX(Coefficients!$F$37:$F$50,MATCH($B15,Coefficients!$A$37:$A$50,0)))) -> 0.27018414 | Y15: =IF($A15="","",$B$8+V15+W15+X15+N(R15)) -> -0.37515437 | Z15: =IF($A15="","",EXP(Y15/(1-$B$7))) -> 0.16498967 | AA15: =IF($A15="","",Z15*INDEX($C$38:$C$40,MATCH($C15,$A$38:$A$40,0))^(-$B$7)/$B$42) -> 0.087190555 | AB15: =IF($A15="","",AA15*(1-$B$6)/$B$43) -> 0.11606645 | AC15: =IF($A15="","",AA15/$B$45*$B$5) -> 4228290.4 | AD15: =IF($A15="","",RANK(AB15,$AB$14:$AB$33)) -> 3
A16: PCF | B16: PCF | C16: L | E16: 1 | F16: 3.09 | G16: 1 | H16: 3.52 | I16: 1.5 | J16: 9 | K16: 2.83 | L16: 6 | M16: 5.67 | N16: 4.5 | O16: 9 | P16: 6 | Q16: 1.5 | R16: 0 | S16: =IF($A16="","",IF($B16="NEW",5,INDEX(Fiscal!C:C,MATCH($B16,Fiscal!$A:$A,0)))) -> 9 | T16: =IF($A16="","",IF($B16="NEW",5,INDEX(Fiscal!D:D,MATCH($B16,Fiscal!$A:$A,0)))) -> 6 | U16: =IF($A16="","",IF($B16="NEW",5,INDEX(Fiscal!E:E,MATCH($B16,Fiscal!$A:$A,0)))) -> 1.5 | V16: =IF($A16="","",SUMPRODUCT($E$11:$N$11,E16:N16-5)) -> 0.0094620794 | W16: =IF($A16="","",$B$9*SUMPRODUCT($O$12:$Q$12,O16:Q16-S16:U16)) -> 0 | X16: =IF($A16="","",IF($B16="NEW",0,INDEX(Coefficients!$F$37:$F$50,MATCH($B16,Coefficients!$A$37:$A$50,0)))) -> -0.12365514 | Y16: =IF($A16="","",$B$8+V16+W16+X16+N(R16)) -> -0.59573483 | Z16: =IF($A16="","",EXP(Y16/(1-$B$7))) -> 0.057192994 | AA16: =IF($A16="","",Z16*INDEX($C$38:$C$40,MATCH($C16,$A$38:$A$40,0))^(-$B$7)/$B$42) -> 0.030224249 | AB16: =IF($A16="","",AA16*(1-$B$6)/$B$43) -> 0.04023396 | AC16: =IF($A16="","",AA16/$B$45*$B$5) -> 1465719.6 | AD16: =IF($A16="","",RANK(AB16,$AB$14:$AB$33)) -> 8
A17: Les Écologistes | B17: EELV | C17: L | E17: 1.33 | F17: 1.6 | G17: 1.5 | H17: 8.67 | I17: 2 | J17: 8.6 | K17: 2.17 | L17: 9.25 | M17: 8 | N17: 7 | O17: 8 | P17: 5.5 | Q17: 2 | R17: 0 | S17: =IF($A17="","",IF($B17="NEW",5,INDEX(Fiscal!C:C,MATCH($B17,Fiscal!$A:$A,0)))) -> 8 | T17: =IF($A17="","",IF($B17="NEW",5,INDEX(Fiscal!D:D,MATCH($B17,Fiscal!$A:$A,0)))) -> 5.5 | U17: =IF($A17="","",IF($B17="NEW",5,INDEX(Fiscal!E:E,MATCH($B17,Fiscal!$A:$A,0)))) -> 2 | V17: =IF($A17="","",SUMPRODUCT($E$11:$N$11,E17:N17-5)) -> 0.049272139 | W17: =IF($A17="","",$B$9*SUMPRODUCT($O$12:$Q$12,O17:Q17-S17:U17)) -> 0 | X17: =IF($A17="","",IF($B17="NEW",0,INDEX(Coefficients!$F$37:$F$50,MATCH($B17,Coefficients!$A$37:$A$50,0)))) -> -0.016186363 | Y17: =IF($A17="","",$B$8+V17+W17+X17+N(R17)) -> -0.44845599 | Z17: =IF($A17="","",EXP(Y17/(1-$B$7))) -> 0.11602597 | AA17: =IF($A17="","",Z17*INDEX($C$38:$C$40,MATCH($C17,$A$38:$A$40,0))^(-$B$7)/$B$42) -> 0.061315162 | AB17: =IF($A17="","",AA17*(1-$B$6)/$B$43) -> 0.081621606 | AC17: =IF($A17="","",AA17/$B$45*$B$5) -> 2973467.8 | AD17: =IF($A17="","",RANK(AB17,$AB$14:$AB$33)) -> 5
A18: PS / Place publique | B18: PS | C18: L | E18: 1.67 | F18: 3.18 | G18: 2 | H18: 8.79 | I18: 3 | J18: 7.8 | K18: 2.83 | L18: 6.75 | M18: 6.67 | N18: 7.67 | O18: 7.5 | P18: 5.5 | Q18: 2.5 | R18: 0 | S18: =IF($A18="","",IF($B18="NEW",5,INDEX(Fiscal!C:C,MATCH($B18,Fiscal!$A:$A,0)))) -> 7.5 | T18: =IF($A18="","",IF($B18="NEW",5,INDEX(Fiscal!D:D,MATCH($B18,Fiscal!$A:$A,0)))) -> 5.5 | U18: =IF($A18="","",IF($B18="NEW",5,INDEX(Fiscal!E:E,MATCH($B18,Fiscal!$A:$A,0)))) -> 2.5 | V18: =IF($A18="","",SUMPRODUCT($E$11:$N$11,E18:N18-5)) -> 0.1952889 | W18: =IF($A18="","",$B$9*SUMPRODUCT($O$12:$Q$12,O18:Q18-S18:U18)) -> 0 | X18: =IF($A18="","",IF($B18="NEW",0,INDEX(Coefficients!$F$37:$F$50,MATCH($B18,Coefficients!$A$37:$A$50,0)))) -> -0.3015066 | Y18: =IF($A18="","",$B$8+V18+W18+X18+N(R18)) -> -0.58775947 | Z18: =IF($A18="","",EXP(Y18/(1-$B$7))) -> 0.059426318 | AA18: =IF($A18="","",Z18*INDEX($C$38:$C$40,MATCH($C18,$A$38:$A$40,0))^(-$B$7)/$B$42) -> 0.031404473 | AB18: =IF($A18="","",AA18*(1-$B$6)/$B$43) -> 0.041805052 | AC18: =IF($A18="","",AA18/$B$45*$B$5) -> 1522954.3 | AD18: =IF($A18="","",RANK(AB18,$AB$14:$AB$33)) -> 7
A19: Ensemble | B19: ENS | C19: C | E19: 6.32 | F19: 5.55 | G19: 6.1 | H19: 9 | I19: 4.95 | J19: 3.92 | K19: 5.38 | L19: 5.5 | M19: 4.26 | N19: 8.14 | O19: 5.45 | P19: 6.4 | Q19: 6.35 | R19: 0 | S19: =IF($A19="","",IF($B19="NEW",5,INDEX(Fiscal!C:C,MATCH($B19,Fiscal!$A:$A,0)))) -> 5.45 | T19: =IF($A19="","",IF($B19="NEW",5,INDEX(Fiscal!D:D,MATCH($B19,Fiscal!$A:$A,0)))) -> 6.4 | U19: =IF($A19="","",IF($B19="NEW",5,INDEX(Fiscal!E:E,MATCH($B19,Fiscal!$A:$A,0)))) -> 6.35 | V19: =IF($A19="","",SUMPRODUCT($E$11:$N$11,E19:N19-5)) -> 0.143923 | W19: =IF($A19="","",$B$9*SUMPRODUCT($O$12:$Q$12,O19:Q19-S19:U19)) -> 0 | X19: =IF($A19="","",IF($B19="NEW",0,INDEX(Coefficients!$F$37:$F$50,MATCH($B19,Coefficients!$A$37:$A$50,0)))) -> -0.0023877565 | Y19: =IF($A19="","",$B$8+V19+W19+X19+N(R19)) -> -0.34000653 | Z19: =IF($A19="","",EXP(Y19/(1-$B$7))) -> 0.19533158 | AA19: =IF($A19="","",Z19*INDEX($C$38:$C$40,MATCH($C19,$A$38:$A$40,0))^(-$B$7)/$B$42) -> 0.18937628 | AB19: =IF($A19="","",AA19*(1-$B$6)/$B$43) -> 0.25209419 | AC19: =IF($A19="","",AA19/$B$45*$B$5) -> 9183769 | AD19: =IF($A19="","",RANK(AB19,$AB$14:$AB$33)) -> 1
A20: LR | B20: LR | C20: R | E20: 7.33 | F20: 8.36 | G20: 7.5 | H20: 7.12 | I20: 7 | J20: 2.6 | K20: 7.83 | L20: 4 | M20: 2.67 | N20: 7 | O20: 4.5 | P20: 7 | Q20: 7.5 | R20: 0 | S20: =IF($A20="","",IF($B20="NEW",5,INDEX(Fiscal!C:C,MATCH($B20,Fiscal!$A:$A,0)))) -> 4.5 | T20: =IF($A20="","",IF($B20="NEW",5,INDEX(Fiscal!D:D,MATCH($B20,Fiscal!$A:$A,0)))) -> 7 | U20: =IF($A20="","",IF($B20="NEW",5,INDEX(Fiscal!E:E,MATCH($B20,Fiscal!$A:$A,0)))) -> 7.5 | V20: =IF($A20="","",SUMPRODUCT($E$11:$N$11,E20:N20-5)) -> 0.27984729 | W20: =IF($A20="","",$B$9*SUMPRODUCT($O$12:$Q$12,O20:Q20-S20:U20)) -> 0 | X20: =IF($A20="","",IF($B20="NEW",0,INDEX(Coefficients!$F$37:$F$50,MATCH($B20,Coefficients!$A$37:$A$50,0)))) -> 0.10723136 | Y20: =IF($A20="","",$B$8+V20+W20+X20+N(R20)) -> -0.094463121 | Z20: =IF($A20="","",EXP(Y20/(1-$B$7))) -> 0.63526828 | AA20: =IF($A20="","",Z20*INDEX($C$38:$C$40,MATCH($C20,$A$38:$A$40,0))^(-$B$7)/$B$42) -> 0.081404265 | AB20: =IF($A20="","",AA20*(1-$B$6)/$B$43) -> 0.10836385 | AC20: =IF($A20="","",AA20/$B$45*$B$5) -> 3947685.3 | AD20: =IF($A20="","",RANK(AB20,$AB$14:$AB$33)) -> 4
A21: Debout la France | B21: DLF | C21: R | E21: 6.5 | F21: 9.33 | G21: 5 | H21: 0.71 | I21: 6.5 | J21: 3.6 | K21: 9 | L21: 3 | M21: 3.5 | N21: 5 | O21: 6 | P21: 6.5 | Q21: 5 | R21: 0 | S21: =IF($A21="","",IF($B21="NEW",5,INDEX(Fiscal!C:C,MATCH($B21,Fiscal!$A:$A,0)))) -> 6 | T21: =IF($A21="","",IF($B21="NEW",5,INDEX(Fiscal!D:D,MATCH($B21,Fiscal!$A:$A,0)))) -> 6.5 | U21: =IF($A21="","",IF($B21="NEW",5,INDEX(Fiscal!E:E,MATCH($B21,Fiscal!$A:$A,0)))) -> 5 | V21: =IF($A21="","",SUMPRODUCT($E$11:$N$11,E21:N21-5)) -> 0.22326162 | W21: =IF($A21="","",$B$9*SUMPRODUCT($O$12:$Q$12,O21:Q21-S21:U21)) -> 0 | X21: =IF($A21="","",IF($B21="NEW",0,INDEX(Coefficients!$F$37:$F$50,MATCH($B21,Coefficients!$A$37:$A$50,0)))) -> -0.11226056 | Y21: =IF($A21="","",$B$8+V21+W21+X21+N(R21)) -> -0.37054071 | Z21: =IF($A21="","",EXP(Y21/(1-$B$7))) -> 0.16868657 | AA21: =IF($A21="","",Z21*INDEX($C$38:$C$40,MATCH($C21,$A$38:$A$40,0))^(-$B$7)/$B$42) -> 0.021615759 | AB21: =IF($A21="","",AA21*(1-$B$6)/$B$43) -> 0.028774498 | AC21: =IF($A21="","",AA21/$B$45*$B$5) -> 1048252.4 | AD21: =IF($A21="","",RANK(AB21,$AB$14:$AB$33)) -> 9
A22: RN | B22: RN | C22: R | E22: 4.33 | F22: 9.55 | G22: 3.5 | H22: 1.97 | I22: 7.5 | J22: 5.3 | K22: 8.83 | L22: 2.5 | M22: 2 | N22: 2.33 | O22: 7 | P22: 6.5 | Q22: 4.5 | R22: 0 | S22: =IF($A22="","",IF($B22="NEW",5,INDEX(Fiscal!C:C,MATCH($B22,Fiscal!$A:$A,0)))) -> 7 | T22: =IF($A22="","",IF($B22="NEW",5,INDEX(Fiscal!D:D,MATCH($B22,Fiscal!$A:$A,0)))) -> 6.5 | U22: =IF($A22="","",IF($B22="NEW",5,INDEX(Fiscal!E:E,MATCH($B22,Fiscal!$A:$A,0)))) -> 4.5 | V22: =IF($A22="","",SUMPRODUCT($E$11:$N$11,E22:N22-5)) -> 0.44061912 | W22: =IF($A22="","",$B$9*SUMPRODUCT($O$12:$Q$12,O22:Q22-S22:U22)) -> 0 | X22: =IF($A22="","",IF($B22="NEW",0,INDEX(Coefficients!$F$37:$F$50,MATCH($B22,Coefficients!$A$37:$A$50,0)))) -> 0.11105237 | Y22: =IF($A22="","",$B$8+V22+W22+X22+N(R22)) -> 0.070129719 | Z22: =IF($A22="","",EXP(Y22/(1-$B$7))) -> 1.4005068 | AA22: =IF($A22="","",Z22*INDEX($C$38:$C$40,MATCH($C22,$A$38:$A$40,0))^(-$B$7)/$B$42) -> 0.17946311 | AB22: =IF($A22="","",AA22*(1-$B$6)/$B$43) -> 0.23889797 | AC22: =IF($A22="","",AA22/$B$45*$B$5) -> 8703031.6 | AD22: =IF($A22="","",RANK(AB22,$AB$14:$AB$33)) -> 2
A23: Reconquête | B23: REC | C23: R | E23: 8.5 | F23: 9.67 | G23: 6 | H23: 1.06 | I23: 9 | J23: 2.11 | K23: 9.5 | L23: 1.67 | M23: 2.17 | N23: 5 | O23: 5.5 | P23: 7 | Q23: 8 | R23: 0 | S23: =IF($A23="","",IF($B23="NEW",5,INDEX(Fiscal!C:C,MATCH($B23,Fiscal!$A:$A,0)))) -> 5.5 | T23: =IF($A23="","",IF($B23="NEW",5,INDEX(Fiscal!D:D,MATCH($B23,Fiscal!$A:$A,0)))) -> 7 | U23: =IF($A23="","",IF($B23="NEW",5,INDEX(Fiscal!E:E,MATCH($B23,Fiscal!$A:$A,0)))) -> 8 | V23: =IF($A23="","",SUMPRODUCT($E$11:$N$11,E23:N23-5)) -> 0.17809368 | W23: =IF($A23="","",$B$9*SUMPRODUCT($O$12:$Q$12,O23:Q23-S23:U23)) -> 0 | X23: =IF($A23="","",IF($B23="NEW",0,INDEX(Coefficients!$F$37:$F$50,MATCH($B23,Coefficients!$A$37:$A$50,0)))) -> 0.060718044 | Y23: =IF($A23="","",$B$8+V23+W23+X23+N(R23)) -> -0.24273005 | Z23: =IF($A23="","",EXP(Y23/(1-$B$7))) -> 0.31166192 | AA23: =IF($A23="","",Z23*INDEX($C$38:$C$40,MATCH($C23,$A$38:$A$40,0))^(-$B$7)/$B$42) -> 0.039936843 | AB23: =IF($A23="","",AA23*(1-$B$6)/$B$43) -> 0.053163184 | AC23: =IF($A23="","",AA23/$B$45*$B$5) -> 1936730.1 | AD23: =IF($A23="","",RANK(AB23,$AB$14:$AB$33)) -> 6
S24: =IF($A24="","",IF($B24="NEW",5,INDEX(Fiscal!C:C,MATCH($B24,Fiscal!$A:$A,0)))) | T24: =IF($A24="","",IF($B24="NEW",5,INDEX(Fiscal!D:D,MATCH($B24,Fiscal!$A:$A,0)))) | U24: =IF($A24="","",IF($B24="NEW",5,INDEX(Fiscal!E:E,MATCH($B24,Fiscal!$A:$A,0)))) | V24: =IF($A24="","",SUMPRODUCT($E$11:$N$11,E24:N24-5)) | W24: =IF($A24="","",$B$9*SUMPRODUCT($O$12:$Q$12,O24:Q24-S24:U24)) | X24: =IF($A24="","",IF($B24="NEW",0,INDEX(Coefficients!$F$37:$F$50,MATCH($B24,Coefficients!$A$37:$A$50,0)))) | Y24: =IF($A24="","",$B$8+V24+W24+X24+N(R24)) | Z24: =IF($A24="","",EXP(Y24/(1-$B$7))) | AA24: =IF($A24="","",Z24*INDEX($C$38:$C$40,MATCH($C24,$A$38:$A$40,0))^(-$B$7)/$B$42) | AB24: =IF($A24="","",AA24*(1-$B$6)/$B$43) | AC24: =IF($A24="","",AA24/$B$45*$B$5) | AD24: =IF($A24="","",RANK(AB24,$AB$14:$AB$33))
S25: =IF($A25="","",IF($B25="NEW",5,INDEX(Fiscal!C:C,MATCH($B25,Fiscal!$A:$A,0)))) | T25: =IF($A25="","",IF($B25="NEW",5,INDEX(Fiscal!D:D,MATCH($B25,Fiscal!$A:$A,0)))) | U25: =IF($A25="","",IF($B25="NEW",5,INDEX(Fiscal!E:E,MATCH($B25,Fiscal!$A:$A,0)))) | V25: =IF($A25="","",SUMPRODUCT($E$11:$N$11,E25:N25-5)) | W25: =IF($A25="","",$B$9*SUMPRODUCT($O$12:$Q$12,O25:Q25-S25:U25)) | X25: =IF($A25="","",IF($B25="NEW",0,INDEX(Coefficients!$F$37:$F$50,MATCH($B25,Coefficients!$A$37:$A$50,0)))) | Y25: =IF($A25="","",$B$8+V25+W25+X25+N(R25)) | Z25: =IF($A25="","",EXP(Y25/(1-$B$7))) | AA25: =IF($A25="","",Z25*INDEX($C$38:$C$40,MATCH($C25,$A$38:$A$40,0))^(-$B$7)/$B$42) | AB25: =IF($A25="","",AA25*(1-$B$6)/$B$43) | AC25: =IF($A25="","",AA25/$B$45*$B$5) | AD25: =IF($A25="","",RANK(AB25,$AB$14:$AB$33))
S26: =IF($A26="","",IF($B26="NEW",5,INDEX(Fiscal!C:C,MATCH($B26,Fiscal!$A:$A,0)))) | T26: =IF($A26="","",IF($B26="NEW",5,INDEX(Fiscal!D:D,MATCH($B26,Fiscal!$A:$A,0)))) | U26: =IF($A26="","",IF($B26="NEW",5,INDEX(Fiscal!E:E,MATCH($B26,Fiscal!$A:$A,0)))) | V26: =IF($A26="","",SUMPRODUCT($E$11:$N$11,E26:N26-5)) | W26: =IF($A26="","",$B$9*SUMPRODUCT($O$12:$Q$12,O26:Q26-S26:U26)) | X26: =IF($A26="","",IF($B26="NEW",0,INDEX(Coefficients!$F$37:$F$50,MATCH($B26,Coefficients!$A$37:$A$50,0)))) | Y26: =IF($A26="","",$B$8+V26+W26+X26+N(R26)) | Z26: =IF($A26="","",EXP(Y26/(1-$B$7))) | AA26: =IF($A26="","",Z26*INDEX($C$38:$C$40,MATCH($C26,$A$38:$A$40,0))^(-$B$7)/$B$42) | AB26: =IF($A26="","",AA26*(1-$B$6)/$B$43) | AC26: =IF($A26="","",AA26/$B$45*$B$5) | AD26: =IF($A26="","",RANK(AB26,$AB$14:$AB$33))
S27: =IF($A27="","",IF($B27="NEW",5,INDEX(Fiscal!C:C,MATCH($B27,Fiscal!$A:$A,0)))) | T27: =IF($A27="","",IF($B27="NEW",5,INDEX(Fiscal!D:D,MATCH($B27,Fiscal!$A:$A,0)))) | U27: =IF($A27="","",IF($B27="NEW",5,INDEX(Fiscal!E:E,MATCH($B27,Fiscal!$A:$A,0)))) | V27: =IF($A27="","",SUMPRODUCT($E$11:$N$11,E27:N27-5)) | W27: =IF($A27="","",$B$9*SUMPRODUCT($O$12:$Q$12,O27:Q27-S27:U27)) | X27: =IF($A27="","",IF($B27="NEW",0,INDEX(Coefficients!$F$37:$F$50,MATCH($B27,Coefficients!$A$37:$A$50,0)))) | Y27: =IF($A27="","",$B$8+V27+W27+X27+N(R27)) | Z27: =IF($A27="","",EXP(Y27/(1-$B$7))) | AA27: =IF($A27="","",Z27*INDEX($C$38:$C$40,MATCH($C27,$A$38:$A$40,0))^(-$B$7)/$B$42) | AB27: =IF($A27="","",AA27*(1-$B$6)/$B$43) | AC27: =IF($A27="","",AA27/$B$45*$B$5) | AD27: =IF($A27="","",RANK(AB27,$AB$14:$AB$33))
S28: =IF($A28="","",IF($B28="NEW",5,INDEX(Fiscal!C:C,MATCH($B28,Fiscal!$A:$A,0)))) | T28: =IF($A28="","",IF($B28="NEW",5,INDEX(Fiscal!D:D,MATCH($B28,Fiscal!$A:$A,0)))) | U28: =IF($A28="","",IF($B28="NEW",5,INDEX(Fiscal!E:E,MATCH($B28,Fiscal!$A:$A,0)))) | V28: =IF($A28="","",SUMPRODUCT($E$11:$N$11,E28:N28-5)) | W28: =IF($A28="","",$B$9*SUMPRODUCT($O$12:$Q$12,O28:Q28-S28:U28)) | X28: =IF($A28="","",IF($B28="NEW",0,INDEX(Coefficients!$F$37:$F$50,MATCH($B28,Coefficients!$A$37:$A$50,0)))) | Y28: =IF($A28="","",$B$8+V28+W28+X28+N(R28)) | Z28: =IF($A28="","",EXP(Y28/(1-$B$7))) | AA28: =IF($A28="","",Z28*INDEX($C$38:$C$40,MATCH($C28,$A$38:$A$40,0))^(-$B$7)/$B$42) | AB28: =IF($A28="","",AA28*(1-$B$6)/$B$43) | AC28: =IF($A28="","",AA28/$B$45*$B$5) | AD28: =IF($A28="","",RANK(AB28,$AB$14:$AB$33))
S29: =IF($A29="","",IF($B29="NEW",5,INDEX(Fiscal!C:C,MATCH($B29,Fiscal!$A:$A,0)))) | T29: =IF($A29="","",IF($B29="NEW",5,INDEX(Fiscal!D:D,MATCH($B29,Fiscal!$A:$A,0)))) | U29: =IF($A29="","",IF($B29="NEW",5,INDEX(Fiscal!E:E,MATCH($B29,Fiscal!$A:$A,0)))) | V29: =IF($A29="","",SUMPRODUCT($E$11:$N$11,E29:N29-5)) | W29: =IF($A29="","",$B$9*SUMPRODUCT($O$12:$Q$12,O29:Q29-S29:U29)) | X29: =IF($A29="","",IF($B29="NEW",0,INDEX(Coefficients!$F$37:$F$50,MATCH($B29,Coefficients!$A$37:$A$50,0)))) | Y29: =IF($A29="","",$B$8+V29+W29+X29+N(R29)) | Z29: =IF($A29="","",EXP(Y29/(1-$B$7))) | AA29: =IF($A29="","",Z29*INDEX($C$38:$C$40,MATCH($C29,$A$38:$A$40,0))^(-$B$7)/$B$42) | AB29: =IF($A29="","",AA29*(1-$B$6)/$B$43) | AC29: =IF($A29="","",AA29/$B$45*$B$5) | AD29: =IF($A29="","",RANK(AB29,$AB$14:$AB$33))
S30: =IF($A30="","",IF($B30="NEW",5,INDEX(Fiscal!C:C,MATCH($B30,Fiscal!$A:$A,0)))) | T30: =IF($A30="","",IF($B30="NEW",5,INDEX(Fiscal!D:D,MATCH($B30,Fiscal!$A:$A,0)))) | U30: =IF($A30="","",IF($B30="NEW",5,INDEX(Fiscal!E:E,MATCH($B30,Fiscal!$A:$A,0)))) | V30: =IF($A30="","",SUMPRODUCT($E$11:$N$11,E30:N30-5)) | W30: =IF($A30="","",$B$9*SUMPRODUCT($O$12:$Q$12,O30:Q30-S30:U30)) | X30: =IF($A30="","",IF($B30="NEW",0,INDEX(Coefficients!$F$37:$F$50,MATCH($B30,Coefficients!$A$37:$A$50,0)))) | Y30: =IF($A30="","",$B$8+V30+W30+X30+N(R30)) | Z30: =IF($A30="","",EXP(Y30/(1-$B$7))) | AA30: =IF($A30="","",Z30*INDEX($C$38:$C$40,MATCH($C30,$A$38:$A$40,0))^(-$B$7)/$B$42) | AB30: =IF($A30="","",AA30*(1-$B$6)/$B$43) | AC30: =IF($A30="","",AA30/$B$45*$B$5) | AD30: =IF($A30="","",RANK(AB30,$AB$14:$AB$33))
S31: =IF($A31="","",IF($B31="NEW",5,INDEX(Fiscal!C:C,MATCH($B31,Fiscal!$A:$A,0)))) | T31: =IF($A31="","",IF($B31="NEW",5,INDEX(Fiscal!D:D,MATCH($B31,Fiscal!$A:$A,0)))) | U31: =IF($A31="","",IF($B31="NEW",5,INDEX(Fiscal!E:E,MATCH($B31,Fiscal!$A:$A,0)))) | V31: =IF($A31="","",SUMPRODUCT($E$11:$N$11,E31:N31-5)) | W31: =IF($A31="","",$B$9*SUMPRODUCT($O$12:$Q$12,O31:Q31-S31:U31)) | X31: =IF($A31="","",IF($B31="NEW",0,INDEX(Coefficients!$F$37:$F$50,MATCH($B31,Coefficients!$A$37:$A$50,0)))) | Y31: =IF($A31="","",$B$8+V31+W31+X31+N(R31)) | Z31: =IF($A31="","",EXP(Y31/(1-$B$7))) | AA31: =IF($A31="","",Z31*INDEX($C$38:$C$40,MATCH($C31,$A$38:$A$40,0))^(-$B$7)/$B$42) | AB31: =IF($A31="","",AA31*(1-$B$6)/$B$43) | AC31: =IF($A31="","",AA31/$B$45*$B$5) | AD31: =IF($A31="","",RANK(AB31,$AB$14:$AB$33))
S32: =IF($A32="","",IF($B32="NEW",5,INDEX(Fiscal!C:C,MATCH($B32,Fiscal!$A:$A,0)))) | T32: =IF($A32="","",IF($B32="NEW",5,INDEX(Fiscal!D:D,MATCH($B32,Fiscal!$A:$A,0)))) | U32: =IF($A32="","",IF($B32="NEW",5,INDEX(Fiscal!E:E,MATCH($B32,Fiscal!$A:$A,0)))) | V32: =IF($A32="","",SUMPRODUCT($E$11:$N$11,E32:N32-5)) | W32: =IF($A32="","",$B$9*SUMPRODUCT($O$12:$Q$12,O32:Q32-S32:U32)) | X32: =IF($A32="","",IF($B32="NEW",0,INDEX(Coefficients!$F$37:$F$50,MATCH($B32,Coefficients!$A$37:$A$50,0)))) | Y32: =IF($A32="","",$B$8+V32+W32+X32+N(R32)) | Z32: =IF($A32="","",EXP(Y32/(1-$B$7))) | AA32: =IF($A32="","",Z32*INDEX($C$38:$C$40,MATCH($C32,$A$38:$A$40,0))^(-$B$7)/$B$42) | AB32: =IF($A32="","",AA32*(1-$B$6)/$B$43) | AC32: =IF($A32="","",AA32/$B$45*$B$5) | AD32: =IF($A32="","",RANK(AB32,$AB$14:$AB$33))
S33: =IF($A33="","",IF($B33="NEW",5,INDEX(Fiscal!C:C,MATCH($B33,Fiscal!$A:$A,0)))) | T33: =IF($A33="","",IF($B33="NEW",5,INDEX(Fiscal!D:D,MATCH($B33,Fiscal!$A:$A,0)))) | U33: =IF($A33="","",IF($B33="NEW",5,INDEX(Fiscal!E:E,MATCH($B33,Fiscal!$A:$A,0)))) | V33: =IF($A33="","",SUMPRODUCT($E$11:$N$11,E33:N33-5)) | W33: =IF($A33="","",$B$9*SUMPRODUCT($O$12:$Q$12,O33:Q33-S33:U33)) | X33: =IF($A33="","",IF($B33="NEW",0,INDEX(Coefficients!$F$37:$F$50,MATCH($B33,Coefficients!$A$37:$A$50,0)))) | Y33: =IF($A33="","",$B$8+V33+W33+X33+N(R33)) | Z33: =IF($A33="","",EXP(Y33/(1-$B$7))) | AA33: =IF($A33="","",Z33*INDEX($C$38:$C$40,MATCH($C33,$A$38:$A$40,0))^(-$B$7)/$B$42) | AB33: =IF($A33="","",AA33*(1-$B$6)/$B$43) | AC33: =IF($A33="","",AA33/$B$45*$B$5) | AD33: =IF($A33="","",RANK(AB33,$AB$14:$AB$33))
A35: Nested logit aggregation
A37: Nest | B37: Name | C37: D_g = sum exp(U/(1-sigma)) | D37: D_g^(1-sigma)
A38: L | B38: Left | C38: =SUMIF($C$14:$C$33,A38,$Z$14:$Z$33) -> 0.42034961 | D38: =IF(C38>0,C38^(1-$B$7),0) -> 0.83490063
A39: C | B39: Centre | C39: =SUMIF($C$14:$C$33,A39,$Z$14:$Z$33) -> 0.19533158 | D39: =IF(C39>0,C39^(1-$B$7),0) -> 0.71176568
A40: R | B40: Right | C40: =SUMIF($C$14:$C$33,A40,$Z$14:$Z$33) -> 2.5161236 | D40: =IF(C40>0,C40^(1-$B$7),0) -> 1.2118069
A42: Denominator 1 + sum D_g^(1-sigma) | B42: =1+SUM(D38:D40) -> 3.7584732
A43: Listed candidates, share of registered | B43: =SUM(AA14:AA33) -> 0.73393451
A44: Minor candidates, share of registered (before rescaling) | B44: =B6*B43/(1-B6) -> 0.017277885
A45: Rescaling factor 1 + minor | B45: =1+B44 -> 1.0172779
...

Sheet Elections
A1: Elections (first rounds)
A2: Official Interior Ministry / Conseil constitutionnel results. Outside option = abstention + blank + null.
A4: Election | B4: Label | C4: Type | D4: Positions period | E4: Registered | F4: Valid votes | G4: Votes for listed parties | H4: Valid votes for unlisted candidates | I4: Outside share s0
A5: P2017 | B5: Presidential 2017, round 1 | C5: P | D5: 2019 | E5: 47582183 | F5: 36054394 | G5: =SUMIF(Votes!$A:$A,A5,Votes!$D:$D) -> 35553507 | H5: =F5-G5 -> 500887 | I5: =1-F5/E5 -> 0.24227112
A6: L2017 | B6: Legislative 2017, round 1 | C6: L | D6: 2019 | E6: 47570988 | F6: 22654164 | G6: =SUMIF(Votes!$A:$A,A6,Votes!$D:$D) -> 20787549 | H6: =F6-G6 -> 1866615 | I6: =1-F6/E6 -> 0.52378193
A7: E2019 | B7: European 2019 | C7: E | D7: 2019 | E7: 47345328 | F7: 22655174 | G7: =SUMIF(Votes!$A:$A,A7,Votes!$D:$D) -> 20122507 | H7: =F7-G7 -> 2532667 | I7: =1-F7/E7 -> 0.52149082
A8: P2022 | B8: Presidential 2022, round 1 | C8: P | D8: 2024 | E8: 48747876 | F8: 35132947 | G8: =SUMIF(Votes!$A:$A,A8,Votes!$D:$D) -> 34031560 | H8: =F8-G8 -> 1101387 | I8: =1-F8/E8 -> 0.27929276
A9: L2022 | B9: Legislative 2022, round 1 | C9: L | D9: 2024 | E9: 48953748 | F9: 22744708 | G9: =SUMIF(Votes!$A:$A,A9,Votes!$D:$D) -> 19741669 | H9: =F9-G9 -> 3003039 | I9: =1-F9/E9 -> 0.53538373
A10: E2024 | B10: European 2024 | C10: E | D10: 2024 | E10: 49462981 | F10: 24753773 | G10: =SUMIF(Votes!$A:$A,A10,Votes!$D:$D) -> 22987690 | H10: =F10-G10 -> 1766083 | I10: =1-F10/E10 -> 0.49954951
A11: L2024 | B11: Legislative 2024, round 1 | C11: L | D11: 2024 | E11: 49332709 | F11: 32057946 | G11: =SUMIF(Votes!$A:$A,A11,Votes!$D:$D) -> 29012208 | H11: =F11-G11 -> 3045738 | I11: =1-F11/E11 -> 0.35016855

Sheet Votes
A1: Votes by party and election
A2: Shares are of registered voters. Nest: L = Left, C = Centre, R = Right.
A4: Election | B4: Party | C4: Party name | D4: Votes | E4: Nest | F4: Registered | G4: Share s_j | H4: Outside share s0 | I4: ln(s_j/s0) | J4: Nest share | K4: ln s_j|g | L4: Note
A5: P2017 | B5: ENS | C5: Ensemble | D5: 8656346 | E5: C | F5: =INDEX(Elections!$E:$E,MATCH(A5,Elections!$A:$A,0)) -> 47582183 | G5: =D5/F5 -> 0.1819241 | H5: =INDEX(Elections!$I:$I,MATCH(A5,Elections!$A:$A,0)) -> 0.24227112 | I5: =LN(G5)-LN(H5) -> -0.28646786 | J5: =SUMIFS($G:$G,$A:$A,A5,$E:$E,E5) -> 0.1819241 | K5: =LN(G5/J5) -> 0
A6: P2017 | B6: RN | C6: RN | D6: 7678491 | E6: R | F6: =INDEX(Elections!$E:$E,MATCH(A6,Elections!$A:$A,0)) -> 47582183 | G6: =D6/F6 -> 0.16137324 | H6: =INDEX(Elections!$I:$I,MATCH(A6,Elections!$A:$A,0)) -> 0.24227112 | I6: =LN(G6)-LN(H6) -> -0.40633751 | J6: =SUMIFS($G:$G,$A:$A,A6,$E:$E,E6) -> 0.35557496 | K6: =LN(G6/J6) -> -0.79001616
A7: P2017 | B7: LR | C7: LR | D7: 7212995 | E7: R | F7: =INDEX(Elections!$E:$E,MATCH(A7,Elections!$A:$A,0)) -> 47582183 | G7: =D7/F7 -> 0.15159025 | H7: =INDEX(Elections!$I:$I,MATCH(A7,Elections!$A:$A,0)) -> 0.24227112 | I7: =LN(G7)-LN(H7) -> -0.46887629 | J7: =SUMIFS($G:$G,$A:$A,A7,$E:$E,E7) -> 0.35557496 | K7: =LN(G7/J7) -> -0.85255494
A8: P2017 | B8: LFI | C8: La France insoumise | D8: 7059951 | E8: L | F8: =INDEX(Elections!$E:$E,MATCH(A8,Elections!$A:$A,0)) -> 47582183 | G8: =D8/F8 -> 0.14837384 | H8: =INDEX(Elections!$I:$I,MATCH(A8,Elections!$A:$A,0)) -> 0.24227112 | I8: =LN(G8)-LN(H8) -> -0.49032244 | J8: =SUMIFS($G:$G,$A:$A,A8,$E:$E,E8) -> 0.20970303 | K8: =LN(G8/J8) -> -0.34595739
A9: P2017 | B9: PS | C9: PS / Place publique | D9: 2291288 | E9: L | F9: =INDEX(Elections!$E:$E,MATCH(A9,Elections!$A:$A,0)) -> 47582183 | G9: =D9/F9 -> 0.048154327 | H9: =INDEX(Elections!$I:$I,MATCH(A9,Elections!$A:$A,0)) -> 0.24227112 | I9: =LN(G9)-LN(H9) -> -1.6156465 | J9: =SUMIFS($G:$G,$A:$A,A9,$E:$E,E9) -> 0.20970303 | K9: =LN(G9/J9) -> -1.4712814
A10: P2017 | B10: DLF | C10: Debout la France | D10: 1695000 | E10: R | F10: =INDEX(Elections!$E:$E,MATCH(A10,Elections!$A:$A,0)) -> 47582183 | G10: =D10/F10 -> 0.035622577 | H10: =INDEX(Elections!$I:$I,MATCH(A10,Elections!$A:$A,0)) -> 0.24227112 | I10: =LN(G10)-LN(H10) -> -1.9170778 | J10: =SUMIFS($G:$G,$A:$A,A10,$E:$E,E10) -> 0.35557496 | K10: =LN(G10/J10) -> -2.3007565
A11: P2017 | B11: LONPA | C11: LO / NPA | D11: 626889 | E11: L | F11: =INDEX(Elections!$E:$E,MATCH(A11,Elections!$A:$A,0)) -> 47582183 | G11: =D11/F11 -> 0.013174868 | H11: =INDEX(Elections!$I:$I,MATCH(A11,Elections!$A:$A,0)) -> 0.24227112 | I11: =LN(G11)-LN(H11) -> -2.9117463 | J11: =SUMIFS($G:$G,$A:$A,A11,$E:$E,E11) -> 0.20970303 | K11: =LN(G11/J11) -> -2.7673813
A12: P2017 | B12: UPR | C12: UPR / Patriotes | D12: 332547 | E12: R | F12: =INDEX(Elections!$E:$E,MATCH(A12,Elections!$A:$A,0)) -> 47582183 | G12: =D12/F12 -> 0.0069888975 | H12: =INDEX(Elections!$I:$I,MATCH(A12,Elections!$A:$A,0)) -> 0.24227112 | I12: =LN(G12)-LN(H12) -> -3.5457346 | J12: =SUMIFS($G:$G,$A:$A,A12,$E:$E,E12) -> 0.35557496 | K12: =LN(G12/J12) -> -3.9294133
A13: L2017 | B13: ENS | C13: Ensemble | D13: 7323496 | E13: C | F13: =INDEX(Elections!$E:$E,MATCH(A13,Elections!$A:$A,0)) -> 47570988 | G13: =D13/F13 -> 0.15394879 | H13: =INDEX(Elections!$I:$I,MATCH(A13,Elections!$A:$A,0)) -> 0.52378193 | I13: =LN(G13)-LN(H13) -> -1.2244554 | J13: =SUMIFS($G:$G,$A:$A,A13,$E:$E,E13) -> 0.15394879 | K13: =LN(G13/J13) -> 0 | L13: REM 6,391,269 + MoDem 932,227 (MoDem: check)
A14: L2017 | B14: LR | C14: LR | D14: 4260652 | E14: R | F14: =INDEX(Elections!$E:$E,MATCH(A14,Elections!$A:$A,0)) -> 47570988 | G14: =D14/F14 -> 0.089564085 | H14: =INDEX(Elections!$I:$I,MATCH(A14,Elections!$A:$A,0)) -> 0.52378193 | I14: =LN(G14)-LN(H14) -> -1.766121 | J14: =SUMIFS($G:$G,$A:$A,A14,$E:$E,E14) -> 0.15800651 | K14: =LN(G14/J14) -> -0.56768186 | L14: LR 3,573,427 + UDI 687,225 (UDI: check)
A15: L2017 | B15: RN | C15: RN | D15: 2990454 | E15: R | F15: =INDEX(Elections!$E:$E,MATCH(A15,Elections!$A:$A,0)) -> 47570988 | G15: =D15/F15 -> 0.062862979 | H15: =INDEX(Elections!$I:$I,MATCH(A15,Elections!$A:$A,0)) -> 0.52378193 | I15: =LN(G15)-LN(H15) -> -2.120118 | J15: =SUMIFS($G:$G,$A:$A,A15,$E:$E,E15) -> 0.15800651 | K15: =LN(G15/J15) -> -0.92167885
A16: L2017 | B16: LFI | C16: La France insoumise | D16: 2497622 | E16: L | F16: =INDEX(Elections!$E:$E,MATCH(A16,Elections!$A:$A,0)) -> 47570988 | G16: =D16/F16 -> 0.052503051 | H16: =INDEX(Elections!$I:$I,MATCH(A16,Elections!$A:$A,0)) -> 0.52378193 | I16: =LN(G16)-LN(H16) -> -2.3002042 | J16: =SUMIFS($G:$G,$A:$A,A16,$E:$E,E16) -> 0.12502425 | K16: =LN(G16/J16) -> -0.86763642
A17: L2017 | B17: PS | C17: PS / Place publique | D17: 1685677 | E17: L | F17: =INDEX(Elections!$E:$E,MATCH(A17,Elections!$A:$A,0)) -> 47570988 | G17: =D17/F17 -> 0.03543498 | H17: =INDEX(Elections!$I:$I,MATCH(A17,Elections!$A:$A,0)) -> 0.52378193 | I17: =LN(G17)-LN(H17) -> -2.693376 | J17: =SUMIFS($G:$G,$A:$A,A17,$E:$E,E17) -> 0.12502425 | K17: =LN(G17/J17) -> -1.2608082 | L17: check
A18: L2017 | B18: EELV | C18: Les Écologistes | D18: 973527 | E18: L | F18: =INDEX(Elections!$E:$E,MATCH(A18,Elections!$A:$A,0)) -> 47570988 | G18: =D18/F18 -> 0.020464721 | H18: =INDEX(Elections!$I:$I,MATCH(A18,Elections!$A:$A,0)) -> 0.52378193 | I18: =LN(G18)-LN(H18) -> -3.242373 | J18: =SUMIFS($G:$G,$A:$A,A18,$E:$E,E18) -> 0.12502425 | K18: =LN(G18/J18) -> -1.8098052 | L18: check
A19: L2017 | B19: PCF | C19: PCF | D19: 615487 | E19: L | F19: =INDEX(Elections!$E:$E,MATCH(A19,Elections!$A:$A,0)) -> 47570988 | G19: =D19/F19 -> 0.012938285 | H19: =INDEX(Elections!$I:$I,MATCH(A19,Elections!$A:$A,0)) -> 0.52378193 | I19: =LN(G19)-LN(H19) -> -3.7008847 | J19: =SUMIFS($G:$G,$A:$A,A19,$E:$E,E19) -> 0.12502425 | K19: =LN(G19/J19) -> -2.268317 | L19: check
A20: L2017 | B20: DLF | C20: Debout la France | D20: 265420 | E20: R | F20: =INDEX(Elections!$E:$E,MATCH(A20,Elections!$A:$A,0)) -> 47570988 | G20: =D20/F20 -> 0.0055794511 | H20: =INDEX(Elections!$I:$I,MATCH(A20,Elections!$A:$A,0)) -> 0.52378193 | I20: =LN(G20)-LN(H20) -> -4.541985 | J20: =SUMIFS($G:$G,$A:$A,A20,$E:$E,E20) -> 0.15800651 | K20: =LN(G20/J20) -> -3.3435459 | L20: check
A21: L2017 | B21: LONPA | C21: LO / NPA | D21: 175214 | E21: L | F21: =INDEX(Elections!$E:$E,MATCH(A21,Elections!$A:$A,0)) -> 47570988 | G21: =D21/F21 -> 0.0036832113 | H21: =INDEX(Elections!$I:$I,MATCH(A21,Elections!$A:$A,0)) -> 0.52378193 | I21: =LN(G21)-LN(H21) -> -4.9572904 | J21: =SUMIFS($G:$G,$A:$A,A21,$E:$E,E21) -> 0.12502425 | K21: =LN(G21/J21) -> -3.5247227 | L21: EXG, check
A22: E2019 | B22: RN | C22: RN | D22: 5286939 | E22: R | F22: =INDEX(Elections!$E:$E,MATCH(A22,Elections!$A:$A,0)) -> 47345328 | G22: =D22/F22 -> 0.1116676 | H22: =INDEX(Elections!$I:$I,MATCH(A22,Elections!$A:$A,0)) -> 0.52149082 | I22: =LN(G22)-LN(H22) -> -1.5411651 | J22: =SUMIFS($G:$G,$A:$A,A22,$E:$E,E22) -> 0.17774643 | K22: =LN(G22/J22) -> -0.46483141
A23: E2019 | B23: ENS | C23: Ensemble | D23: 5079015 | E23: C | F23: =INDEX(Elections!$E:$E,MATCH(A23,Elections!$A:$A,0)) -> 47345328 | G23: =D23/F23 -> 0.10727595 | H23: =INDEX(Elections!$I:$I,MATCH(A23,Elections!$A:$A,0)) -> 0.52149082 | I23: =LN(G23)-LN(H23) -> -1.5812872 | J23: =SUMIFS($G:$G,$A:$A,A23,$E:$E,E23) -> 0.10727595 | K23: =LN(G23/J23) -> 0
A24: E2019 | B24: EELV | C24: Les Écologistes | D24: 3055023 | E24: L | F24: =INDEX(Elections!$E:$E,MATCH(A24,Elections!$A:$A,0)) -> 47345328 | G24: =D24/F24 -> 0.064526388 | H24: =INDEX(Elections!$I:$I,MATCH(A24,Elections!$A:$A,0)) -> 0.52149082 | I24: =LN(G24)-LN(H24) -> -2.0896174 | J24: =SUMIFS($G:$G,$A:$A,A24,$E:$E,E24) -> 0.13999331 | K24: =LN(G24/J24) -> -0.77452035
A25: E2019 | B25: LR | C25: LR | D25: 1920407 | E25: R | F25: =INDEX(Elections!$E:$E,MATCH(A25,Elections!$A:$A,0)) -> 47345328 | G25: =D25/F25 -> 0.0405617 | H25: =INDEX(Elections!$I:$I,MATCH(A25,Elections!$A:$A,0)) -> 0.52149082 | I25: =LN(G25)-LN(H25) -> -2.5538674 | J25: =SUMIFS($G:$G,$A:$A,A25,$E:$E,E25) -> 0.17774643 | K25: =LN(G25/J25) -> -1.4775337
A26: E2019 | B26: LFI | C26: La France insoumise | D26: 1428548 | E26: L | F26: =INDEX(Elections!$E:$E,MATCH(A26,Elections!$A:$A,0)) -> 47345328 | G26: =D26/F26 -> 0.030172945 | H26: =INDEX(Elections!$I:$I,MATCH(A26,Elections!$A:$A,0)) -> 0.52149082 | I26: =LN(G26)-LN(H26) -> -2.849746 | J26: =SUMIFS($G:$G,$A:$A,A26,$E:$E,E26) -> 0.13999331 | K26: =LN(G26/J26) -> -1.5346489
A27: E2019 | B27: PS | C27: PS / Place publique | D27: 1403170 | E27: L | F27: =INDEX(Elections!$E:$E,MATCH(A27,Elections!$A:$A,0)) -> 47345328 | G27: =D27/F27 -> 0.029636926 | H27: =INDEX(Elections!$I:$I,MATCH(A27,Elections!$A:$A,0)) -> 0.52149082 | I27: =LN(G27)-LN(H27) -> -2.8676706 | J27: =SUMIFS($G:$G,$A:$A,A27,$E:$E,E27) -> 0.13999331 | K27: =LN(G27/J27) -> -1.5525735 | L27: PS–Place publique list
A28: E2019 | B28: DLF | C28: Debout la France | D28: 795508 | E28: R | F28: =INDEX(Elections!$E:$E,MATCH(A28,Elections!$A:$A,0)) -> 47345328 | G28: =D28/F28 -> 0.016802249 | H28: =INDEX(Elections!$I:$I,MATCH(A28,Elections!$A:$A,0)) -> 0.52149082 | I28: =LN(G28)-LN(H28) -> -3.4351789 | J28: =SUMIFS($G:$G,$A:$A,A28,$E:$E,E28) -> 0.17774643 | K28: =LN(G28/J28) -> -2.3588452
A29: E2019 | B29: PCF | C29: PCF | D29: 564949 | E29: L | F29: =INDEX(Elections!$E:$E,MATCH(A29,Elections!$A:$A,0)) -> 47345328 | G29: =D29/F29 -> 0.011932518 | H29: =INDEX(Elections!$I:$I,MATCH(A29,Elections!$A:$A,0)) -> 0.52149082 | I29: =LN(G29)-LN(H29) -> -3.7774244 | J29: =SUMIFS($G:$G,$A:$A,A29,$E:$E,E29) -> 0.13999331 | K29: =LN(G29/J29) -> -2.4623273
A30: E2019 | B30: UPR | C30: UPR / Patriotes | D30: 412609 | E30: R | F30: =INDEX(Elections!$E:$E,MATCH(A30,Elections!$A:$A,0)) -> 47345328 | G30: =D30/F30 -> 0.0087148831 | H30: =INDEX(Elections!$I:$I,MATCH(A30,Elections!$A:$A,0)) -> 0.52149082 | I30: =LN(G30)-LN(H30) -> -4.0916594 | J30: =SUMIFS($G:$G,$A:$A,A30,$E:$E,E30) -> 0.17774643 | K30: =LN(G30/J30) -> -3.0153257 | L30: UPR 265,469 + Patriotes 147,140
A31: E2019 | B31: LONPA | C31: LO / NPA | D31: 176339 | E31: L | F31: =INDEX(Elections!$E:$E,MATCH(A31,Elections!$A:$A,0)) -> 47345328 | G31: =D31/F31 -> 0.003724528 | H31: =INDEX(Elections!$I:$I,MATCH(A31,Elections!$A:$A,0)) -> 0.52149082 | I31: =LN(G31)-LN(H31) -> -4.9417515 | J31: =SUMIFS($G:$G,$A:$A,A31,$E:$E,E31) -> 0.13999331 | K31: =LN(G31/J31) -> -3.6266545
A32: P2022 | B32: ENS | C32: Ensemble | D32: 9783058 | E32: C | F32: =INDEX(Elections!$E:$E,MATCH(A32,Elections!$A:$A,0)) -> 48747876 | G32: =D32/F32 -> 0.20068686 | H32: =INDEX(Elections!$I:$I,MATCH(A32,Elections!$A:$A,0)) -> 0.27929276 | I32: =LN(G32)-LN(H32) -> -0.3305148 | J32: =SUMIFS($G:$G,$A:$A,A32,$E:$E,E32) -> 0.20068686 | K32: =LN(G32/J32) -> 0
A33: P2022 | B33: RN | C33: RN | D33: 8133828 | E33: R | F33: =INDEX(Elections!$E:$E,MATCH(A33,Elections!$A:$A,0)) -> 48747876 | G33: =D33/F33 -> 0.16685502 | H33: =INDEX(Elections!$I:$I,MATCH(A33,Elections!$A:$A,0)) -> 0.27929276 | I33: =LN(G33)-LN(H33) -> -0.51513525 | J33: =SUMIFS($G:$G,$A:$A,A33,$E:$E,E33) -> 0.26715484 | K33: =LN(G33/J33) -> -0.4707031
A34: P2022 | B34: LFI | C34: La France insoumise | D34: 7712520 | E34: L | F34: =INDEX(Elections!$E:$E,MATCH(A34,Elections!$A:$A,0)) -> 48747876 | G34: =D34/F34 -> 0.15821243 | H34: =INDEX(Elections!$I:$I,MATCH(A34,Elections!$A:$A,0)) -> 0.27929276 | I34: =LN(G34)-LN(H34) -> -0.56832193 | J34: =SUMIFS($G:$G,$A:$A,A34,$E:$E,E34) -> 0.230272 | K34: =LN(G34/J34) -> -0.37532259
A35: P2022 | B35: REC | C35: Reconquête | D35: 2485226 | E35: R | F35: =INDEX(Elections!$E:$E,MATCH(A35,Elections!$A:$A,0)) -> 48747876 | G35: =D35/F35 -> 0.050981216 | H35: =INDEX(Elections!$I:$I,MATCH(A35,Elections!$A:$A,0)) -> 0.27929276 | I35: =LN(G35)-LN(H35) -> -1.7008033 | J35: =SUMIFS($G:$G,$A:$A,A35,$E:$E,E35) -> 0.26715484 | K35: =LN(G35/J35) -> -1.6563712
A36: P2022 | B36: LR | C36: LR | D36: 1679001 | E36: R | F36: =INDEX(Elections!$E:$E,MATCH(A36,Elections!$A:$A,0)) -> 48747876 | G36: =D36/F36 -> 0.034442547 | H36: =INDEX(Elections!$I:$I,MATCH(A36,Elections!$A:$A,0)) -> 0.27929276 | I36: =LN(G36)-LN(H36) -> -2.0929679 | J36: =SUMIFS($G:$G,$A:$A,A36,$E:$E,E36) -> 0.26715484 | K36: =LN(G36/J36) -> -2.0485358
A37: P2022 | B37: EELV | C37: Les Écologistes | D37: 1627853 | E37: L | F37: =INDEX(Elections!$E:$E,MATCH(A37,Elections!$A:$A,0)) -> 48747876 | G37: =D37/F37 -> 0.033393311 | H37: =INDEX(Elections!$I:$I,MATCH(A37,Elections!$A:$A,0)) -> 0.27929276 | I37: =LN(G37)-LN(H37) -> -2.1239049 | J37: =SUMIFS($G:$G,$A:$A,A37,$E:$E,E37) -> 0.230272 | K37: =LN(G37/J37) -> -1.9309056
A38: P2022 | B38: PCF | C38: PCF | D38: 802422 | E38: L | F38: =INDEX(Elections!$E:$E,MATCH(A38,Elections!$A:$A,0)) -> 48747876 | G38: =D38/F38 -> 0.016460656 | H38: =INDEX(Elections!$I:$I,MATCH(A38,Elections!$A:$A,0)) -> 0.27929276 | I38: =LN(G38)-LN(H38) -> -2.8312875 | J38: =SUMIFS($G:$G,$A:$A,A38,$E:$E,E38) -> 0.230272 | K38: =LN(G38/J38) -> -2.6382882
A39: P2022 | B39: DLF | C39: Debout la France | D39: 725176 | E39: R | F39: =INDEX(Elections!$E:$E,MATCH(A39,Elections!$A:$A,0)) -> 48747876 | G39: =D39/F39 -> 0.014876053 | H39: =INDEX(Elections!$I:$I,MATCH(A39,Elections!$A:$A,0)) -> 0.27929276 | I39: =LN(G39)-LN(H39) -> -2.9325078 | J39: =SUMIFS($G:$G,$A:$A,A39,$E:$E,E39) -> 0.26715484 | K39: =LN(G39/J39) -> -2.8880757
A40: P2022 | B40: PS | C40: PS / Place publique | D40: 616478 | E40: L | F40: =INDEX(Elections!$E:$E,MATCH(A40,Elections!$A:$A,0)) -> 48747876 | G40: =D40/F40 -> 0.012646254 | H40: =INDEX(Elections!$I:$I,MATCH(A40,Elections!$A:$A,0)) -> 0.27929276 | I40: =LN(G40)-LN(H40) -> -3.0948996 | J40: =SUMIFS($G:$G,$A:$A,A40,$E:$E,E40) -> 0.230272 | K40: =LN(G40/J40) -> -2.9019002
A41: P2022 | B41: LONPA | C41: LO / NPA | D41: 465998 | E41: L | F41: =INDEX(Elections!$E:$E,MATCH(A41,Elections!$A:$A,0)) -> 48747876 | G41: =D41/F41 -> 0.0095593498 | H41: =INDEX(Elections!$I:$I,MATCH(A41,Elections!$A:$A,0)) -> 0.27929276 | I41: =LN(G41)-LN(H41) -> -3.3747408 | J41: =SUMIFS($G:$G,$A:$A,A41,$E:$E,E41) -> 0.230272 | K41: =LN(G41/J41) -> -3.1817415
...

Sheet Positions
A1: Party characteristics (0-10)
A2: Source flags: E19 / E24 = Chapel Hill Expert Survey 2019 / 2024 mean (rescaled where needed); C = constructed coding.
A4: Period | B4: Party | C4: Party name | D4: Tax cuts | E4: Immigration control | F4: Spending control | G4: European integration | H4: Support for Israel | I4: Redistribution | J4: Law and order | K4: Climate action | L4: Other environment | M4: Defence vs Russia | N4: Source: Tax cuts | O4: Source: Immigration control | P4: Source: Spending control | Q4: Source: European integration | R4: Source: Support for Israel | S4: Source: Redistribution | T4: Source: Law and order | U4: Source: Climate action | V4: Source: Other environment | W4: Source: Defence vs Russia
A5: 2024 | B5: LONPA | C5: LO / NPA | D5: 0 | E5: 0 | F5: 0 | G5: 2 | H5: 0.5 | I5: 10 | J5: 0.5 | K5: 6 | L5: 6 | M5: 3 | N5: C | O5: C | P5: C | Q5: C | R5: C | S5: C | T5: C | U5: C | V5: C | W5: C
A6: 2024 | B6: LFI | C6: La France insoumise | D6: 1 | E6: 1.55 | F6: 1 | G6: 3.33 | H6: 1 | I6: 9 | J6: 2 | K6: 7.75 | L6: 6.67 | M6: 5 | N6: E24 | O6: E24 | P6: C | Q6: E24 | R6: C | S6: E24 | T6: E24 | U6: E24 | V6: E24 | W6: E24
A7: 2024 | B7: PCF | C7: PCF | D7: 1 | E7: 3.09 | F7: 1 | G7: 3.52 | H7: 1.5 | I7: 9 | J7: 2.83 | K7: 6 | L7: 5.67 | M7: 4.5 | N7: E24 | O7: E24 | P7: C | Q7: E24 | R7: C | S7: E24 | T7: E24 | U7: E24 | V7: E24 | W7: E24
A8: 2024 | B8: EELV | C8: Les Écologistes | D8: 1.33 | E8: 1.6 | F8: 1.5 | G8: 8.67 | H8: 2 | I8: 8.6 | J8: 2.17 | K8: 9.25 | L8: 8 | M8: 7 | N8: E24 | O8: E24 | P8: C | Q8: E24 | R8: C | S8: E24 | T8: E24 | U8: E24 | V8: E24 | W8: E24
A9: 2024 | B9: PS | C9: PS / Place publique | D9: 1.67 | E9: 3.18 | F9: 2 | G9: 8.79 | H9: 3 | I9: 7.8 | J9: 2.83 | K9: 6.75 | L9: 6.67 | M9: 7.67 | N9: E24 | O9: E24 | P9: C | Q9: E24 | R9: C | S9: E24 | T9: E24 | U9: E24 | V9: E24 | W9: E24
A10: 2024 | B10: RE | C10: Renaissance | D10: 6.5 | E10: 5.73 | F10: 6 | G10: 8.79 | H10: 5 | I10: 3.8 | J10: 5.8 | K10: 5.5 | L10: 4.33 | M10: 8.67 | N10: E24 | O10: E24 | P10: C | Q10: E24 | R10: C | S10: E24 | T10: E24 | U10: E24 | V10: E24 | W10: E24
A11: 2024 | B11: MoDem | C11: MoDem | D11: 5.33 | E11: 4.67 | F11: 6 | G11: 9.7 | H11: 4.5 | I11: 4.5 | J11: 3.83 | K11: 5.5 | L11: 4.33 | M11: 6.67 | N11: E24 | O11: E24 | P11: C | Q11: E24 | R11: C | S11: E24 | T11: E24 | U11: E24 | V11: E24 | W11: E24
A12: 2024 | B12: HOR | C12: Horizons | D12: 7 | E12: 6 | F12: 7 | G12: 9.07 | H12: 5.5 | I12: 3.6 | J12: 5.5 | K12: 5.5 | L12: 3.67 | M12: 7.33 | N12: E24 | O12: E24 | P12: C | Q12: E24 | R12: C | S12: E24 | T12: E24 | U12: E24 | V12: E24 | W12: E24
A13: 2024 | B13: LR | C13: LR | D13: 7.33 | E13: 8.36 | F13: 7.5 | G13: 7.12 | H13: 7 | I13: 2.6 | J13: 7.83 | K13: 4 | L13: 2.67 | M13: 7 | N13: E24 | O13: E24 | P13: C | Q13: E24 | R13: C | S13: E24 | T13: E24 | U13: E24 | V13: E24 | W13: E24
A14: 2024 | B14: UDR | C14: UDR (Ciotti) | D14: 8 | E14: 9 | F14: 5.5 | G14: 3 | H14: 8 | I14: 3 | J14: 9 | K14: 2.5 | L14: 2.5 | M14: 5 | N14: C | O14: C | P14: C | Q14: C | R14: C | S14: C | T14: C | U14: C | V14: C | W14: C
A15: 2024 | B15: DLF | C15: Debout la France | D15: 6.5 | E15: 9.33 | F15: 5 | G15: 0.71 | H15: 6.5 | I15: 3.6 | J15: 9 | K15: 3 | L15: 3.5 | M15: 5 | N15: E19 | O15: E19 | P15: C | Q15: E19 | R15: C | S15: E19 | T15: E19 | U15: C | V15: E19 | W15: C
A16: 2024 | B16: RN | C16: RN | D16: 4.33 | E16: 9.55 | F16: 3.5 | G16: 1.97 | H16: 7.5 | I16: 5.3 | J16: 8.83 | K16: 2.5 | L16: 2 | M16: 2.33 | N16: E24 | O16: E24 | P16: C | Q16: E24 | R16: C | S16: E24 | T16: E24 | U16: E24 | V16: E24 | W16: E24
... A32: 2019 | B32: UPR | C32: UPR / Patriotes | D32: 5 | E32: 7 | F32: 5 | G32: 0 | H32: 3 | I32: 5 | J32: 7 | K32: 3 | L32: 3 | M32: 2 | N32: C | O32: C | P32: C | Q32: C | R32: C | S32: C | T32: C | U32: C | V32: C | W32: C
A34: Scale
A35: Code | B35: Characteristic | C35: 0 means | D35: 10 means | E35: Source
A36: tax | B36: Tax cuts | C36: Tax increases | D36: Strong tax cuts | E36: CHES spendvtax
A37: immig | B37: Immigration control | C37: More immigration | D37: Remigration | E37: CHES immigrate_policy
A38: spend | B38: Spending control | C38: Large spending rise | D38: Strong control | E38: Constructed from Institut Montaigne costings
A39: eu | B39: European integration | C39: Frexit | D39: Federal union | E39: CHES eu_position, (x−1)/6×10
A40: israel | B40: Support for Israel | C40: Strongly critical | D40: Strong support | E40: Constructed from statements and votes
A41: redis | B41: Redistribution | C41: Against | D41: Strongly for | E41: 10 − CHES redistribution
A42: order | B42: Law and order | C42: Civil liberties | D42: Tough on crime | E42: CHES civlib_laworder
A43: climate | B43: Climate action | C43: Growth over climate policy | D43: Climate policy first | E43: 10 − CHES climate_change (2024 wave; carried back to 2017–2019)
A44: env | B44: Other environment | C44: Growth first | D44: Environmental protection first | E44: 10 − CHES environment (environmental sustainability)
A45: ukr | B45: Defence vs Russia | C45: Trade with Russia | D45: Invest in defence | E45: 10 − CHES eu_russia (2024 wave)

Sheet Composites
A1: Coalition weights
A2: Ensemble mixes Renaissance, MoDem and Horizons; NUPES and NFP mix their parties by number of candidacies.
A4: Coalition | B4: Period | C4: Member | D4: Weight
A5: ENS | B5: 2019 | C5: RE | D5: 0.8
A6: ENS | B6: 2019 | C6: MoDem | D6: 0.2
A7: ENS | B7: 2024 | C7: RE | D7: 0.7
A8: ENS | B8: 2024 | C8: MoDem | D8: 0.2
A9: ENS | B9: 2024 | C9: HOR | D9: 0.1
A10: NUPES | B10: 2019 | C10: LFI | D10: 326
A11: NUPES | B11: 2019 | C11: EELV | D11: 100
A12: NUPES | B12: 2019 | C12: PS | D12: 70
A13: NUPES | B13: 2019 | C13: PCF | D13: 50
A14: NUPES | B14: 2024 | C14: LFI | D14: 326
A15: NUPES | B15: 2024 | C15: EELV | D15: 100
A16: NUPES | B16: 2024 | C16: PS | D16: 70
... A25: NFP | B25: 2024 | C25: PCF | D25: 50

Sheet Fiscal
A1: Promised fiscal gain by income group
A2: 0 = large loss, 5 = neutral, 10 = large gain. Coded from manifestos (direction reliable, magnitudes are judgement). Coalitions = weighted mix of members (2024 weights).
A4: Party | B4: Party name | C4: Poor (< EUR 1,250/month) | D4: Middle (EUR 1,250-3,000) | E4: Rich (> EUR 3,000) | F4: Main measures behind the coding
A5: LONPA | B5: LO / NPA | C5: 9.5 | D5: 6 | E5: 0.5 | F5: Heavy taxation of capital and high incomes; large minimum-wage and benefit rises
A6: LFI | B6: La France insoumise | C6: 9 | D6: 6.5 | E6: 1 | F6: 14-bracket income tax, cuts below ~€4,000 net/month, ISF restored, flat tax abolished; minimum wage €1,600 net
A7: PCF | B7: PCF | C7: 9 | D7: 6 | E7: 1.5 | F7: Similar to LFI; higher minimum wage and pensions
A8: EELV | B8: Les Écologistes | C8: 8 | D8: 5.5 | E8: 2 | F8: Climate ISF, higher inheritance tax on large estates; targeted transfers
A9: PS | B9: PS / Place publique | C9: 7.5 | D9: 5.5 | E9: 2.5 | F9: ISF restored, more progressive CSG; moderate transfers
A10: RE | B10: Renaissance | C10: 5.5 | D10: 6.5 | E10: 6.5 | F10: Middle-class income tax cut (~€2bn), no ISF, flat tax kept
A11: MoDem | B11: MoDem | C11: 5.5 | D11: 6 | E11: 5.5 | F11: Close to Renaissance, more redistributive rhetoric
A12: HOR | B12: Horizons | C12: 5 | D12: 6.5 | E12: 7 | F12: Lower taxes on work and capital, spending cuts
A13: LR | B13: LR | C13: 4.5 | D13: 7 | E13: 7.5 | F13: Payroll and middle-class tax cuts, lower inheritance tax
A14: UDR | B14: UDR (Ciotti) | C14: 5 | D14: 7 | E14: 7.5 | F14: Tax cuts close to LR/RN
A15: DLF | B15: Debout la France | C15: 6 | D15: 6.5 | E15: 5 | F15: Mixed: VAT and energy cuts, some wealth taxation
A16: RN | B16: RN | C16: 7 | D16: 6.5 | E16: 4.5 | F16: VAT on energy 20%→5.5%, full family share from 2nd child, youth exemption; IFI replaced by a tax on financial wealth
... A18: UPR | B18: UPR / Patriotes | C18: 6 | D18: 6 | E18: 4 | F18: Sovereigntist; mixed fiscal promises
A19: ENS | B19: Ensemble | C19: =(Composites!$D$7*C10+Composites!$D$8*C11+Composites!$D$9*C12)/(Composites!$D$7+Composites!$D$8+Composites!$D$9) -> 5.45 | D19: =(Composites!$D$7*D10+Composites!$D$8*D11+Composites!$D$9*D12)/(Composites!$D$7+Composites!$D$8+Composites!$D$9) -> 6.4 | E19: =(Composites!$D$7*E10+Composites!$D$8*E11+Composites!$D$9*E12)/(Composites!$D$7+Composites!$D$8+Composites!$D$9) -> 6.35 | F19: weighted mix of members
A20: NUPES | B20: NUPES (2022) | C20: =(Composites!$D$14*C6+Composites!$D$15*C8+Composites!$D$16*C9+Composites!$D$17*C7)/(Composites!$D$14+Composites!$D$15+Composites!$D$16+Composites!$D$17) -> 8.6245421 | D20: =(Composites!$D$14*D6+Composites!$D$15*D8+Composites!$D$16*D9+Composites!$D$17*D7)/(Composites!$D$14+Composites!$D$15+Composites!$D$16+Composites!$D$17) -> 6.1428571 | E20: =(Composites!$D$14*E6+Composites!$D$15*E8+Composites!$D$16*E9+Composites!$D$17*E7)/(Composites!$D$14+Composites!$D$15+Composites!$D$16+Composites!$D$17) -> 1.4212454 | F20: weighted mix of members
A21: NFP | B21: Nouveau Front populaire | C21: =(Composites!$D$22*C6+Composites!$D$23*C9+Composites!$D$24*C8+Composites!$D$25*C7)/(Composites!$D$22+Composites!$D$23+Composites!$D$24+Composites!$D$25) -> 8.3507326 | D21: =(Composites!$D$22*D6+Composites!$D$23*D9+Composites!$D$24*D8+Composites!$D$25*D7)/(Composites!$D$22+Composites!$D$23+Composites!$D$24+Composites!$D$25) -> 5.9652015 | E21: =(Composites!$D$22*E6+Composites!$D$23*E9+Composites!$D$24*E8+Composites!$D$25*E7)/(Composites!$D$22+Composites!$D$23+Composites!$D$24+Composites!$D$25) -> 1.6950549 | F21: weighted mix of members

Sheet Income survey
A1: Vote by household income (% of valid votes) and abstention (%)
A2: Ipsos post-election surveys. Legislative 2024 abstention by income is imputed from the European 2024 pattern.
A4: Election | B4: Source | C4: Column | D4: Poor | E4: Middle | F4: Rich
A5: P2022 | B5: Ipsos–Sopra Steria, 6–9 April 2022, n=4,000 | C5: LONPA | D5: 1 | E5: 0.91 | F5: 1
A6: P2022 | B6: Ipsos–Sopra Steria, 6–9 April 2022, n=4,000 | C6: LFI | D6: 30 | E6: 23.18 | F6: 19
A7: P2022 | B7: Ipsos–Sopra Steria, 6–9 April 2022, n=4,000 | C7: PCF | D7: 1 | E7: 3 | F7: 2
A8: P2022 | B8: Ipsos–Sopra Steria, 6–9 April 2022, n=4,000 | C8: EELV | D8: 5 | E8: 5 | F8: 4
A9: P2022 | B9: Ipsos–Sopra Steria, 6–9 April 2022, n=4,000 | C9: PS | D9: 1 | E9: 1 | F9: 2
A10: P2022 | B10: Ipsos–Sopra Steria, 6–9 April 2022, n=4,000 | C10: ENS | D10: 13 | E10: 24.64 | F10: 34
A11: P2022 | B11: Ipsos–Sopra Steria, 6–9 April 2022, n=4,000 | C11: LR | D11: 2 | E11: 4.09 | F11: 6
A12: P2022 | B12: Ipsos–Sopra Steria, 6–9 April 2022, n=4,000 | C12: LAS | D12: 2 | E12: 3 | F12: 4
A13: P2022 | B13: Ipsos–Sopra Steria, 6–9 April 2022, n=4,000 | C13: DLF | D13: 4 | E13: 2.09 | F13: 2
A14: P2022 | B14: Ipsos–Sopra Steria, 6–9 April 2022, n=4,000 | C14: RN | D14: 31 | E14: 26.09 | F14: 19
A15: P2022 | B15: Ipsos–Sopra Steria, 6–9 April 2022, n=4,000 | C15: REC | D15: 10 | E15: 7 | F15: 7
A16: P2022 | B16: Ipsos–Sopra Steria, 6–9 April 2022, n=4,000 | C16: Abstention | D16: 34 | E16: 26.9 | F16: 23
... A32: L2024 | B32: Ipsos-Talan, 27–28 June 2024, n=10,286 | C32: Abstention (imputed) | D32: 41.3 | E32: 33.2 | F32: 31.1
A34: Population weights
A35: Poor (< €1,250/month) | D35: 0.12
A36: Middle (€1,250–3,000) | D36: 0.47
A37: Rich (> €3,000) | D37: 0.41

Sheet Coefficients
A1: Estimated coefficients (2SLS, robust HC1 standard errors)
A2: Blue values come from the estimation in logit2027v4.html; black cells are formulas. Characteristics are centred at 5.
A4: Code | B4: Characteristic | C4: In model | D4: beta | E4: s.e. | F4: t | G4: Within-nest per point beta/(1-sigma) | H4: 0 means | I4: 10 means
A5: tax | B5: Tax cuts | C5: Yes | D5: -0.035747289 | E5: 0.060511252 | F5: =D5/E5 -> -0.59075442 | G5: =D5/(1-$D$16) -> -0.1716948 | H5: Tax increases | I5: Strong tax cuts
A6: immig | B6: Immigration control | C6: Yes | D6: 0.1054539 | E6: 0.038819983 | F6: =D6/E6 -> 2.7164851 | G6: =D6/(1-$D$16) -> 0.50649677 | H6: More immigration | I6: Remigration
A7: spend | B7: Spending control | C7: Yes | D7: -0.037615351 | E7: 0.062722857 | F7: =D7/E7 -> -0.59970724 | G7: =D7/(1-$D$16) -> -0.18066713 | H7: Large spending rise | I7: Strong control
A8: eu | B8: European integration | C8: Yes | D8: 0.043685654 | E8: 0.025790938 | F8: =D8/E8 -> 1.6938373 | G8: =D8/(1-$D$16) -> 0.20982289 | H8: Frexit | I8: Federal union
A9: israel | B9: Support for Israel | C9: Yes | D9: 0.0051190743 | E9: 0.03939512 | F9: =D9/E9 -> 0.12994184 | G9: =D9/(1-$D$16) -> 0.024586995 | H9: Strongly critical | I9: Strong support
A10: redis | B10: Redistribution | C10: No | D10: 0 | H10: Against | I10: Strongly for
A11: order | B11: Law and order | C11: No | D11: 0 | H11: Civil liberties | I11: Tough on crime
A12: climate | B12: Climate action | C12: No | D12: 0 | H12: Growth over climate policy | I12: Climate policy first
A13: env | B13: Other environment | C13: No | D13: 0 | H13: Growth first | I13: Environmental protection first
A14: ukr | B14: Defence vs Russia | C14: No | D14: 0 | H14: Trade with Russia | I14: Invest in defence
B16: sigma (within-nest correlation) | D16: 0.79179748 | E16: 0.07482121 | F16: =D16/E16 -> 10.582527
B17: gamma (own promised fiscal gain, income model) | D17: 0.057890855 | E17: 0.027917358 | F17: =D17/E17 -> 2.0736509
B18: Candidate shock s.d. (eps) | D18: =SQRT(SUMSQ('Estimation data'!AG5:AG64)/(COUNT('Estimation data'!AG5:AG64)-COUNTA($A$37:$A$50))) -> 0.16885095 | G18: residual spread net of party factors
A20: Election | B20: Label | D20: Fixed effect lambda_t
A21: P2017 | B21: Presidential 2017, round 1 | D21: -0.33497902
A22: L2017 | B22: Legislative 2017, round 1 | D22: -1.7803596
A23: E2019 | B23: European 2019 | D23: -1.7047758
A24: P2022 | B24: Presidential 2022, round 1 | D24: -0.62810452
A25: L2022 | B25: Legislative 2022, round 1 | D25: -1.6955918
A26: E2024 | B26: European 2024 | D26: -1.5187526
A27: L2024 | B27: Legislative 2024, round 1 | D27: -0.95976758
B28: lambda_P presidential intercept (mean of P2017 and P2022) | D28: =AVERAGE(D21,D24) -> -0.48154177
B30: Fit
B31: Observations | D31: 60
B32: Parameters | D32: 13
B33: R-squared (with fixed effects) | D33: 0.97786756
B34: First-stage F, excluded instruments | D34: 2.8467937
A36: Party | B36: Party name | C36: Elections | D36: X_j all elections | E36: X_j presidential | F36: X_j used for 2027
A37: LONPA | B37: LO / NPA | C37: =COUNTIF('Estimation data'!$B$5:$B$64,A37) -> 7 | D37: =AVERAGEIF('Estimation data'!$B$5:$B$64,A37,'Estimation data'!$AE$5:$AE$64) -> -0.047303757 | E37: =IF((COUNTIFS('Estimation data'!$B$5:$B$64,A37,'Estimation data'!$A$5:$A$64,"P2017")+COUNTIFS('Estimation data'!$B$5:$B$64,A37,'Estimation data'!$A$5:$A$64,"P2022"))=0,"",(SUMIFS('Estimation data'!$AE$5:$AE$64,'Estimation data'!$B$5:$B$64,A37,'Estimation data'!$A$5:$A$64,"P2017")+SUMIFS('Estimation data'!$AE$5:$AE$64,'Estimation data'!$B$5:$B$64,A37,'Estimation data'!$A$5:$A$64,"P2022"))/(COUNTIFS('Estimation data'!$B$5:$B$64,A37,'Estimation data'!$A$5:$A$64,"P2017")+COUNTIFS('Estimation data'!$B$5:$B$64,A37,'Estimation data'!$A$5:$A$64,"P2022"))) -> 0.0080975116 | F37: =IF(E37="",D37,E37) -> 0.0080975116
A38: LFI | B38: La France insoumise | C38: =COUNTIF('Estimation data'!$B$5:$B$64,A38) -> 5 | D38: =AVERAGEIF('Estimation data'!$B$5:$B$64,A38,'Estimation data'!$AE$5:$AE$64) -> 0.17716643 | E38: =IF((COUNTIFS('Estimation data'!$B$5:$B$64,A38,'Estimation data'!$A$5:$A$64,"P2017")+COUNTIFS('Estimation data'!$B$5:$B$64,A38,'Estimation data'!$A$5:$A$64,"P2022"))=0,"",(SUMIFS('Estimation data'!$AE$5:$AE$64,'Estimation data'!$B$5:$B$64,A38,'Estimation data'!$A$5:$A$64,"P2017")+SUMIFS('Estimation data'!$AE$5:$AE$64,'Estimation data'!$B$5:$B$64,A38,'Estimation data'!$A$5:$A$64,"P2022"))/(COUNTIFS('Estimation data'!$B$5:$B$64,A38,'Estimation data'!$A$5:$A$64,"P2017")+COUNTIFS('Estimation data'!$B$5:$B$64,A38,'Estimation data'!$A$5:$A$64,"P2022"))) -> 0.27018414 | F38: =IF(E38="",D38,E38) -> 0.27018414
A39: PCF | B39: PCF | C39: =COUNTIF('Estimation data'!$B$5:$B$64,A39) -> 4 | D39: =AVERAGEIF('Estimation data'!$B$5:$B$64,A39,'Estimation data'!$AE$5:$AE$64) -> -0.15427035 | E39: =IF((COUNTIFS('Estimation data'!$B$5:$B$64,A39,'Estimation data'!$A$5:$A$64,"P2017")+COUNTIFS('Estimation data'!$B$5:$B$64,A39,'Estimation data'!$A$5:$A$64,"P2022"))=0,"",(SUMIFS('Estimation data'!$AE$5:$AE$64,'Estimation data'!$B$5:$B$64,A39,'Estimation data'!$A$5:$A$64,"P2017")+SUMIFS('Estimation data'!$AE$5:$AE$64,'Estimation data'!$B$5:$B$64,A39,'Estimation data'!$A$5:$A$64,"P2022"))/(COUNTIFS('Estimation data'!$B$5:$B$64,A39,'Estimation data'!$A$5:$A$64,"P2017")+COUNTIFS('Estimation data'!$B$5:$B$64,A39,'Estimation data'!$A$5:$A$64,"P2022"))) -> -0.12365514 | F39: =IF(E39="",D39,E39) -> -0.12365514
A40: EELV | B40: Les Écologistes | C40: =COUNTIF('Estimation data'!$B$5:$B$64,A40) -> 4 | D40: =AVERAGEIF('Estimation data'!$B$5:$B$64,A40,'Estimation data'!$AE$5:$AE$64) -> 0.014008812 | E40: =IF((COUNTIFS('Estimation data'!$B$5:$B$64,A40,'Estimation data'!$A$5:$A$64,"P2017")+COUNTIFS('Estimation data'!$B$5:$B$64,A40,'Estimation data'!$A$5:$A$64,"P2022"))=0,"",(SUMIFS('Estimation data'!$AE$5:$AE$64,'Estimation data'!$B$5:$B$64,A40,'Estimation data'!$A$5:$A$64,"P2017")+SUMIFS('Estimation data'!$AE$5:$AE$64,'Estimation data'!$B$5:$B$64,A40,'Estimation data'!$A$5:$A$64,"P2022"))/(COUNTIFS('Estimation data'!$B$5:$B$64,A40,'Estimation data'!$A$5:$A$64,"P2017")+COUNTIFS('Estimation data'!$B$5:$B$64,A40,'Estimation data'!$A$5:$A$64,"P2022"))) -> -0.016186363 | F40: =IF(E40="",D40,E40) -> -0.016186363
A41: PS | B41: PS / Place publique | C41: =COUNTIF('Estimation data'!$B$5:$B$64,A41) -> 5 | D41: =AVERAGEIF('Estimation data'!$B$5:$B$64,A41,'Estimation data'!$AE$5:$AE$64) -> -0.1360669 | E41: =IF((COUNTIFS('Estimation data'!$B$5:$B$64,A41,'Estimation data'!$A$5:$A$64,"P2017")+COUNTIFS('Estimation data'!$B$5:$B$64,A41,'Estimation data'!$A$5:$A$64,"P2022"))=0,"",(SUMIFS('Estimation data'!$AE$5:$AE$64,'Estimation data'!$B$5:$B$64,A41,'Estimation data'!$A$5:$A$64,"P2017")+SUMIFS('Estimation data'!$AE$5:$AE$64,'Estimation data'!$B$5:$B$64,A41,'Estimation data'!$A$5:$A$64,"P2022"))/(COUNTIFS('Estimation data'!$B$5:$B$64,A41,'Estimation data'!$A$5:$A$64,"P2017")+COUNTIFS('Estimation data'!$B$5:$B$64,A41,'Estimation data'!$A$5:$A$64,"P2022"))) -> -0.3015066 | F41: =IF(E41="",D41,E41) -> -0.3015066
A42: NUPES | B42: NUPES (2022) | C42: =COUNTIF('Estimation data'!$B$5:$B$64,A42) -> 1 | D42: =AVERAGEIF('Estimation data'!$B$5:$B$64,A42,'Estimation data'!$AE$5:$AE$64) -> 0.29176106 | E42: =IF((COUNTIFS('Estimation data'!$B$5:$B$64,A42,'Estimation data'!$A$5:$A$64,"P2017")+COUNTIFS('Estimation data'!$B$5:$B$64,A42,'Estimation data'!$A$5:$A$64,"P2022"))=0,"",(SUMIFS('Estimation data'!$AE$5:$AE$64,'Estimation data'!$B$5:$B$64,A42,'Estimation data'!$A$5:$A$64,"P2017")+SUMIFS('Estimation data'!$AE$5:$AE$64,'Estimation data'!$B$5:$B$64,A42,'Estimation data'!$A$5:$A$64,"P2022"))/(COUNTIFS('Estimation data'!$B$5:$B$64,A42,'Estimation data'!$A$5:$A$64,"P2017")+COUNTIFS('Estimation data'!$B$5:$B$64,A42,'Estimation data'!$A$5:$A$64,"P2022"))) | F42: =IF(E42="",D42,E42) -> 0.29176106
